#VRML_SIM R2023b utf8
# license: Apache License 2.0
# license url: http://www.apache.org/licenses/LICENSE-2.0
# This is a proto file for Webots for the HolonomicRobot
# Extracted from: /tmp/tmp808xrre6.urdf

PROTO HolonomicRobot [
  field  SFVec3f     translation     0 0 0
  field  SFRotation  rotation        0 0 1 0
  field  SFString    name            "HolonomicRobot"  # Is `Robot.name`.
  field  SFString    controller      "void"            # Is `Robot.controller`.
  field  MFString    controllerArgs  []                # Is `Robot.controllerArgs`.
  field  SFString    customData      ""                # Is `Robot.customData`.
  field  SFBool      supervisor      FALSE             # Is `Robot.supervisor`.
  field  SFBool      synchronization TRUE              # Is `Robot.synchronization`.
  field  SFBool      selfCollision   FALSE             # Is `Robot.selfCollision`.
]
{
  Robot {
    translation IS translation
    rotation IS rotation
    controller IS controller
    controllerArgs IS controllerArgs
    customData IS customData
    supervisor IS supervisor
    synchronization IS synchronization
    selfCollision IS selfCollision
    children [
      Pose {
        translation 0.000000 0.000000 0.065000
        children [
          Shape {
            appearance PBRAppearance {
              baseColor 0.500000 0.500000 0.500000
              roughness 1.000000
              metalness 0
            }
            geometry Cylinder {
              radius 0.075
              height 0.05
            }
          }
        ]
      }
      HingeJoint {
        jointParameters HingeJointParameters {
          axis 1.000000 0.000000 0.000096
          anchor 0.075000 0.000000 0.040000
        }
        device [
          RotationalMotor {
            name "frontL_joint"
            maxTorque 10000
          }
          PositionSensor {
            name "frontL_joint_sensor"
          }
        ]
        endPoint Solid {
          translation 0.075000 0.000000 0.040000
          rotation 0.000000 1.000000 0.000000 1.570700
          children [
            Shape {
              appearance PBRAppearance {
                baseColor 0.500000 0.500000 0.500000
                roughness 1.000000
                metalness 0
              }
              geometry Cylinder {
                radius 0.04
                height 0.02
              }
            }
          ]
          name "frontL"
          boundingObject Cylinder {
            radius 0.04
            height 0.02
          }
          physics Physics {
            density -1
            mass 1.000000
            centerOfMass [ 0.000000 0.000000 0.000000 ]
          }
        }
      }
      HingeJoint {
        jointParameters HingeJointParameters {
          axis -0.500004 0.866023 0.000096
          anchor -0.037500 0.064950 0.040000
        }
        device [
          RotationalMotor {
            name "frontR_joint"
            maxTorque 10000
          }
          PositionSensor {
            name "frontR_joint_sensor"
          }
        ]
        endPoint Solid {
          translation -0.037500 0.064950 0.040000
          rotation -0.654627 0.377947 0.654690 2.418825
          children [
            Shape {
              appearance PBRAppearance {
                baseColor 0.500000 0.500000 0.500000
                roughness 1.000000
                metalness 0
              }
              geometry Cylinder {
                radius 0.04
                height 0.02
              }
            }
          ]
          name "frontR"
          boundingObject Cylinder {
            radius 0.04
            height 0.02
          }
          physics Physics {
            density -1
            mass 1.000000
            centerOfMass [ 0.000000 0.000000 0.000000 ]
          }
        }
      }
      HingeJoint {
        jointParameters HingeJointParameters {
          axis -0.500004 -0.866023 0.000096
          anchor -0.037500 -0.064950 0.040000
        }
        device [
          RotationalMotor {
            name "rear_joint"
            maxTorque 10000
          }
          PositionSensor {
            name "rear_joint_sensor"
          }
        ]
        endPoint Solid {
          translation -0.037500 -0.064950 0.040000
          rotation 0.654627 0.377947 -0.654690 2.418825
          children [
            Shape {
              appearance PBRAppearance {
                baseColor 0.500000 0.500000 0.500000
                roughness 1.000000
                metalness 0
              }
              geometry Cylinder {
                radius 0.04
                height 0.02
              }
            }
          ]
          name "rear"
          boundingObject Cylinder {
            radius 0.04
            height 0.02
          }
          physics Physics {
            density -1
            mass 1.000000
            centerOfMass [ 0.000000 0.000000 0.000000 ]
          }
        }
      }
    ]
    name IS name
    boundingObject Pose {
      translation 0.000000 0.000000 0.065000
      children [
        Cylinder {
          radius 0.075
          height 0.05
        }
      ]
    }
    physics Physics {
      density -1
      mass 1.000000
      centerOfMass [ 0.000000 0.000000 0.065000 ]
    }
  }
}
