<?xml version="1.0"?>
<robot name="/home/hylander/test_ws/src/delta_rho/description/omni.urdf" xmlns:xacro="http://ros.org/wiki/xacro">
  <link name="base_link">
    <visual>
      <origin xyz="0 0 0.03" rpy="0 0 0"/>
      <geometry>
        <cylinder radius="0.1" length="0.15"/>
      </geometry>
    </visual>
    <collision>
      <origin xyz="0 0 0.03" rpy="0 0 0"/>
      <geometry>
        <cylinder radius="0.1" length="0.15"/>
      </geometry>
    </collision>
  </link>
  <link name="wheel 3">
  </link>
  <joint name="base_link_wheel 3_joint" type="fixed">
    <parent link="base_link"/>
    <child link="wheel 3"/>
    <origin xyz="0 0 0" rpy="0 0 -2.103185"/>
  </joint>
  <joint name="wheel3" type="continuous">
    <parent link="wheel 3"/>
    <child link="solid"/>
    <axis xyz="-1 0 0"/>
    <limit effort="10" velocity="10"/>
    <origin xyz="-0.1 0 0" rpy="-1.576237 0 0"/>
  </joint>
  <link name="solid">
    <visual>
      <origin xyz="-0.02 0 0" rpy="3.141593 -1.570793 3.141593"/>
      <geometry>
        <cylinder radius="0.05" length="0.02"/>
      </geometry>
    </visual>
    <collision>
      <origin xyz="-0.02 0 0" rpy="3.141593 -1.570793 3.141593"/>
      <geometry>
        <cylinder radius="0.05" length="0.02"/>
      </geometry>
    </collision>
  </link>
  <joint name="sr8" type="continuous">
    <parent link="solid"/>
    <child link="sr8_0"/>
    <axis xyz="0 0.707107 0.707107"/>
    <origin xyz="-0.02 -0.03535 0.03535" rpy="1.402334 -0.521808 -2.52903"/>
  </joint>
  <link name="sr8_0">
    <visual>
      <origin xyz="0 0 0" rpy="-0.76 0 0"/>
      <geometry>
        <cylinder radius="0.01" length="0.02"/>
      </geometry>
    </visual>
    <collision>
      <origin xyz="0 0 0" rpy="-0.76 0 0"/>
      <geometry>
        <cylinder radius="0.01" length="0.02"/>
      </geometry>
    </collision>
  </link>
  <joint name="sr7" type="continuous">
    <parent link="solid"/>
    <child link="sr7_1"/>
    <axis xyz="0 0.707107 0.707107"/>
    <origin xyz="-0.02 0.03535 -0.03535" rpy="1.553945 0.181544 2.956981"/>
  </joint>
  <link name="sr7_1">
    <visual>
      <origin xyz="0 0 0" rpy="-0.76 0 0"/>
      <geometry>
        <cylinder radius="0.01" length="0.02"/>
      </geometry>
    </visual>
    <collision>
      <origin xyz="0 0 0" rpy="-0.76 0 0"/>
      <geometry>
        <cylinder radius="0.01" length="0.02"/>
      </geometry>
    </collision>
  </link>
  <joint name="sr6" type="continuous">
    <parent link="solid"/>
    <child link="sr6_2"/>
    <axis xyz="0 0 1"/>
    <origin xyz="-0.02 -0.05 0" rpy="0 0 0.778227"/>
  </joint>
  <link name="sr6_2">
    <visual>
      <origin xyz="0 0 0" rpy="0 0 0"/>
      <geometry>
        <cylinder radius="0.01" length="0.02"/>
      </geometry>
    </visual>
    <collision>
      <origin xyz="0 0 0" rpy="0 0 0"/>
      <geometry>
        <cylinder radius="0.01" length="0.02"/>
      </geometry>
    </collision>
  </link>
  <joint name="sr5" type="continuous">
    <parent link="solid"/>
    <child link="sr5_3"/>
    <axis xyz="0 0 1"/>
    <origin xyz="-0.02 0.05 0" rpy="0 0 -2.25749"/>
  </joint>
  <link name="sr5_3">
    <visual>
      <origin xyz="0 0 0" rpy="0 0 0"/>
      <geometry>
        <cylinder radius="0.01" length="0.02"/>
      </geometry>
    </visual>
    <collision>
      <origin xyz="0 0 0" rpy="0 0 0"/>
      <geometry>
        <cylinder radius="0.01" length="0.02"/>
      </geometry>
    </collision>
  </link>
  <joint name="sr4" type="continuous">
    <parent link="solid"/>
    <child link="sr4_4"/>
    <axis xyz="0 -0.707107 0.707107"/>
    <origin xyz="-0.02 -0.03535 -0.03535" rpy="-1.276981 0.640019 -2.301696"/>
  </joint>
  <link name="sr4_4">
    <visual>
      <origin xyz="0 0 0" rpy="-2.27 0 0"/>
      <geometry>
        <cylinder radius="0.01" length="0.02"/>
      </geometry>
    </visual>
    <collision>
      <origin xyz="0 0 0" rpy="-2.27 0 0"/>
      <geometry>
        <cylinder radius="0.01" length="0.02"/>
      </geometry>
    </collision>
  </link>
  <joint name="sr3" type="continuous">
    <parent link="solid"/>
    <child link="sr3_5"/>
    <axis xyz="1 0 0"/>
    <origin xyz="-0.02 0 -0.05" rpy="0.005515 0 0"/>
  </joint>
  <link name="sr3_5">
    <visual>
      <origin xyz="0 0 0" rpy="-1.5708 0 0"/>
      <geometry>
        <cylinder radius="0.01" length="0.02"/>
      </geometry>
    </visual>
    <collision>
      <origin xyz="0 0 0" rpy="-1.5708 0 0"/>
      <geometry>
        <cylinder radius="0.01" length="0.02"/>
      </geometry>
    </collision>
  </link>
  <joint name="sr2" type="continuous">
    <parent link="solid"/>
    <child link="sr2_6"/>
    <axis xyz="0 -0.707107 0.707107"/>
    <origin xyz="-0.02 0.03535 0.03535" rpy="-0.01951 0.195001 -0.198818"/>
  </joint>
  <link name="sr2_6">
    <visual>
      <origin xyz="0 0 0" rpy="-2.27 0 0"/>
      <geometry>
        <cylinder radius="0.01" length="0.02"/>
      </geometry>
    </visual>
    <collision>
      <origin xyz="0 0 0" rpy="-2.27 0 0"/>
      <geometry>
        <cylinder radius="0.01" length="0.02"/>
      </geometry>
    </collision>
  </link>
  <joint name="sr1" type="continuous">
    <parent link="solid"/>
    <child link="sr1_7"/>
    <axis xyz="1 0 0"/>
    <origin xyz="-0.02 0 0.05" rpy="1.740592 0 0"/>
  </joint>
  <link name="sr1_7">
    <visual>
      <origin xyz="0 0 0" rpy="-1.5708 0 0"/>
      <geometry>
        <cylinder radius="0.01" length="0.02"/>
      </geometry>
    </visual>
    <collision>
      <origin xyz="0 0 0" rpy="-1.5708 0 0"/>
      <geometry>
        <cylinder radius="0.01" length="0.02"/>
      </geometry>
    </collision>
  </link>
  <link name="wheel 2">
  </link>
  <joint name="base_link_wheel 2_joint" type="fixed">
    <parent link="base_link"/>
    <child link="wheel 2"/>
    <origin xyz="0 0 0" rpy="0 0 2.09"/>
  </joint>
  <joint name="wheel2" type="continuous">
    <parent link="wheel 2"/>
    <child link="solid_8"/>
    <axis xyz="-1 0 0"/>
    <limit effort="10" velocity="10"/>
    <origin xyz="-0.1 0 0" rpy="3.04441 0 0"/>
  </joint>
  <link name="solid_8">
    <visual>
      <origin xyz="-0.02 0 0" rpy="3.141593 -1.570793 3.141593"/>
      <geometry>
        <cylinder radius="0.05" length="0.02"/>
      </geometry>
    </visual>
    <collision>
      <origin xyz="-0.02 0 0" rpy="3.141593 -1.570793 3.141593"/>
      <geometry>
        <cylinder radius="0.05" length="0.02"/>
      </geometry>
    </collision>
  </link>
  <joint name="sr8_9" type="continuous">
    <parent link="solid_8"/>
    <child link="sr8_10"/>
    <axis xyz="0 0.707107 0.707107"/>
    <origin xyz="-0.02 -0.03535 0.03535" rpy="1.522861 0.300052 2.827038"/>
  </joint>
  <link name="sr8_10">
    <visual>
      <origin xyz="0 0 0" rpy="-0.76 0 0"/>
      <geometry>
        <cylinder radius="0.01" length="0.02"/>
      </geometry>
    </visual>
    <collision>
      <origin xyz="0 0 0" rpy="-0.76 0 0"/>
      <geometry>
        <cylinder radius="0.01" length="0.02"/>
      </geometry>
    </collision>
  </link>
  <joint name="sr7_11" type="continuous">
    <parent link="solid_8"/>
    <child link="sr7_12"/>
    <axis xyz="0 0.707107 0.707107"/>
    <origin xyz="-0.02 0.03535 -0.03535" rpy="0.908675 0.777722 1.745584"/>
  </joint>
  <link name="sr7_12">
    <visual>
      <origin xyz="0 0 0" rpy="-0.76 0 0"/>
      <geometry>
        <cylinder radius="0.01" length="0.02"/>
      </geometry>
    </visual>
    <collision>
      <origin xyz="0 0 0" rpy="-0.76 0 0"/>
      <geometry>
        <cylinder radius="0.01" length="0.02"/>
      </geometry>
    </collision>
  </link>
  <joint name="sr6_13" type="continuous">
    <parent link="solid_8"/>
    <child link="sr6_14"/>
    <axis xyz="0 0 1"/>
    <origin xyz="-0.02 -0.05 0" rpy="0 0 2.375082"/>
  </joint>
  <link name="sr6_14">
    <visual>
      <origin xyz="0 0 0" rpy="0 0 0"/>
      <geometry>
        <cylinder radius="0.01" length="0.02"/>
      </geometry>
    </visual>
    <collision>
      <origin xyz="0 0 0" rpy="0 0 0"/>
      <geometry>
        <cylinder radius="0.01" length="0.02"/>
      </geometry>
    </collision>
  </link>
  <joint name="sr5_15" type="continuous">
    <parent link="solid_8"/>
    <child link="sr5_16"/>
    <axis xyz="0 0 1"/>
    <origin xyz="-0.02 0.05 0" rpy="0 0 -2.741544"/>
  </joint>
  <link name="sr5_16">
    <visual>
      <origin xyz="0 0 0" rpy="0 0 0"/>
      <geometry>
        <cylinder radius="0.01" length="0.02"/>
      </geometry>
    </visual>
    <collision>
      <origin xyz="0 0 0" rpy="0 0 0"/>
      <geometry>
        <cylinder radius="0.01" length="0.02"/>
      </geometry>
    </collision>
  </link>
  <joint name="sr4_17" type="continuous">
    <parent link="solid_8"/>
    <child link="sr4_18"/>
    <axis xyz="0 -0.707107 0.707107"/>
    <origin xyz="-0.02 -0.03535 -0.03535" rpy="-1.310537 -0.614218 2.358864"/>
  </joint>
  <link name="sr4_18">
    <visual>
      <origin xyz="0 0 0" rpy="-2.27 0 0"/>
      <geometry>
        <cylinder radius="0.01" length="0.02"/>
      </geometry>
    </visual>
    <collision>
      <origin xyz="0 0 0" rpy="-2.27 0 0"/>
      <geometry>
        <cylinder radius="0.01" length="0.02"/>
      </geometry>
    </collision>
  </link>
  <joint name="sr3_19" type="continuous">
    <parent link="solid_8"/>
    <child link="sr3_20"/>
    <axis xyz="1 0 0"/>
    <origin xyz="-0.02 0 -0.05" rpy="0.398509 0 0"/>
  </joint>
  <link name="sr3_20">
    <visual>
      <origin xyz="0 0 0" rpy="-1.5708 0 0"/>
      <geometry>
        <cylinder radius="0.01" length="0.02"/>
      </geometry>
    </visual>
    <collision>
      <origin xyz="0 0 0" rpy="-1.5708 0 0"/>
      <geometry>
        <cylinder radius="0.01" length="0.02"/>
      </geometry>
    </collision>
  </link>
  <joint name="sr2_21" type="continuous">
    <parent link="solid_8"/>
    <child link="sr2_22"/>
    <axis xyz="0 -0.707107 0.707107"/>
    <origin xyz="-0.02 0.03535 0.03535" rpy="-1.504564 -0.348583 2.769652"/>
  </joint>
  <link name="sr2_22">
    <visual>
      <origin xyz="0 0 0" rpy="-2.27 0 0"/>
      <geometry>
        <cylinder radius="0.01" length="0.02"/>
      </geometry>
    </visual>
    <collision>
      <origin xyz="0 0 0" rpy="-2.27 0 0"/>
      <geometry>
        <cylinder radius="0.01" length="0.02"/>
      </geometry>
    </collision>
  </link>
  <joint name="sr1_23" type="continuous">
    <parent link="solid_8"/>
    <child link="sr1_24"/>
    <axis xyz="1 0 0"/>
    <origin xyz="-0.02 0 0.05" rpy="0.111652 0 0"/>
  </joint>
  <link name="sr1_24">
    <visual>
      <origin xyz="0 0 0" rpy="-1.5708 0 0"/>
      <geometry>
        <cylinder radius="0.01" length="0.02"/>
      </geometry>
    </visual>
    <collision>
      <origin xyz="0 0 0" rpy="-1.5708 0 0"/>
      <geometry>
        <cylinder radius="0.01" length="0.02"/>
      </geometry>
    </collision>
  </link>
  <link name="wheel 1">
  </link>
  <joint name="base_link_wheel 1_joint" type="fixed">
    <parent link="base_link"/>
    <child link="wheel 1"/>
    <origin xyz="0 0 0" rpy="0 0 0"/>
  </joint>
  <joint name="wheel1" type="continuous">
    <parent link="wheel 1"/>
    <child link="solid_25"/>
    <axis xyz="-1 0 0"/>
    <limit effort="10" velocity="10"/>
    <origin xyz="-0.1 0 0" rpy="-2.398828 0 0"/>
  </joint>
  <link name="solid_25">
    <visual>
      <origin xyz="-0.02 0 0" rpy="3.141593 -1.570793 3.141593"/>
      <geometry>
        <cylinder radius="0.05" length="0.02"/>
      </geometry>
    </visual>
    <collision>
      <origin xyz="-0.02 0 0" rpy="3.141593 -1.570793 3.141593"/>
      <geometry>
        <cylinder radius="0.05" length="0.02"/>
      </geometry>
    </collision>
  </link>
  <joint name="sr8_26" type="continuous">
    <parent link="solid_25"/>
    <child link="sr8_27"/>
    <axis xyz="0 0.707107 0.707107"/>
    <origin xyz="-0.02 -0.03535 0.03535" rpy="1.565796 -0.099671 -3.041422"/>
  </joint>
  <link name="sr8_27">
    <visual>
      <origin xyz="0 0 0" rpy="-0.76 0 0"/>
      <geometry>
        <cylinder radius="0.01" length="0.02"/>
      </geometry>
    </visual>
    <collision>
      <origin xyz="0 0 0" rpy="-0.76 0 0"/>
      <geometry>
        <cylinder radius="0.01" length="0.02"/>
      </geometry>
    </collision>
  </link>
  <joint name="sr7_28" type="continuous">
    <parent link="solid_25"/>
    <child link="sr7_29"/>
    <axis xyz="0 0.707107 0.707107"/>
    <origin xyz="-0.02 0.03535 -0.03535" rpy="0.234037 -0.591472 -0.736488"/>
  </joint>
  <link name="sr7_29">
    <visual>
      <origin xyz="0 0 0" rpy="-0.76 0 0"/>
      <geometry>
        <cylinder radius="0.01" length="0.02"/>
      </geometry>
    </visual>
    <collision>
      <origin xyz="0 0 0" rpy="-0.76 0 0"/>
      <geometry>
        <cylinder radius="0.01" length="0.02"/>
      </geometry>
    </collision>
  </link>
  <joint name="sr6_30" type="continuous">
    <parent link="solid_25"/>
    <child link="sr6_31"/>
    <axis xyz="0 0 1"/>
    <origin xyz="-0.02 -0.05 0" rpy="0 0 0.052859"/>
  </joint>
  <link name="sr6_31">
    <visual>
      <origin xyz="0 0 0" rpy="0 0 0"/>
      <geometry>
        <cylinder radius="0.01" length="0.02"/>
      </geometry>
    </visual>
    <collision>
      <origin xyz="0 0 0" rpy="0 0 0"/>
      <geometry>
        <cylinder radius="0.01" length="0.02"/>
      </geometry>
    </collision>
  </link>
  <joint name="sr5_32" type="continuous">
    <parent link="solid_25"/>
    <child link="sr5_33"/>
    <axis xyz="0 0 1"/>
    <origin xyz="-0.02 0.05 0" rpy="0 0 2.224436"/>
  </joint>
  <link name="sr5_33">
    <visual>
      <origin xyz="0 0 0" rpy="0 0 0"/>
      <geometry>
        <cylinder radius="0.01" length="0.02"/>
      </geometry>
    </visual>
    <collision>
      <origin xyz="0 0 0" rpy="0 0 0"/>
      <geometry>
        <cylinder radius="0.01" length="0.02"/>
      </geometry>
    </collision>
  </link>
  <joint name="sr4_34" type="continuous">
    <parent link="solid_25"/>
    <child link="sr4_35"/>
    <axis xyz="0 -0.707107 0.707107"/>
    <origin xyz="-0.02 -0.03535 -0.03535" rpy="-1.558722 0.154158 -2.985569"/>
  </joint>
  <link name="sr4_35">
    <visual>
      <origin xyz="0 0 0" rpy="-2.27 0 0"/>
      <geometry>
        <cylinder radius="0.01" length="0.02"/>
      </geometry>
    </visual>
    <collision>
      <origin xyz="0 0 0" rpy="-2.27 0 0"/>
      <geometry>
        <cylinder radius="0.01" length="0.02"/>
      </geometry>
    </collision>
  </link>
  <joint name="sr3_36" type="continuous">
    <parent link="solid_25"/>
    <child link="sr3_37"/>
    <axis xyz="1 0 0"/>
    <origin xyz="-0.02 0 -0.05" rpy="-0.521298 0 0"/>
  </joint>
  <link name="sr3_37">
    <visual>
      <origin xyz="0 0 0" rpy="-1.5708 0 0"/>
      <geometry>
        <cylinder radius="0.01" length="0.02"/>
      </geometry>
    </visual>
    <collision>
      <origin xyz="0 0 0" rpy="-1.5708 0 0"/>
      <geometry>
        <cylinder radius="0.01" length="0.02"/>
      </geometry>
    </collision>
  </link>
  <joint name="sr2_38" type="continuous">
    <parent link="solid_25"/>
    <child link="sr2_39"/>
    <axis xyz="0 -0.707107 0.707107"/>
    <origin xyz="-0.02 0.03535 0.03535" rpy="-0.235388 0.592706 -0.73891"/>
  </joint>
  <link name="sr2_39">
    <visual>
      <origin xyz="0 0 0" rpy="-2.27 0 0"/>
      <geometry>
        <cylinder radius="0.01" length="0.02"/>
      </geometry>
    </visual>
    <collision>
      <origin xyz="0 0 0" rpy="-2.27 0 0"/>
      <geometry>
        <cylinder radius="0.01" length="0.02"/>
      </geometry>
    </collision>
  </link>
  <joint name="sr1_40" type="continuous">
    <parent link="solid_25"/>
    <child link="sr1_41"/>
    <axis xyz="1 0 0"/>
    <origin xyz="-0.02 0 0.05" rpy="0.210594 0 0"/>
  </joint>
  <link name="sr1_41">
    <visual>
      <origin xyz="0 0 0" rpy="-1.5708 0 0"/>
      <geometry>
        <cylinder radius="0.01" length="0.02"/>
      </geometry>
    </visual>
    <collision>
      <origin xyz="0 0 0" rpy="-1.5708 0 0"/>
      <geometry>
        <cylinder radius="0.01" length="0.02"/>
      </geometry>
    </collision>
  </link>
</robot>
